<?xml version="1.0" ?>
<!-- =================================================================================== -->
<!-- |    This document was autogenerated by xacro from /home/hiramaki_yudai/shared/catkin_ws/src/khi_robot/khi_rs_description/urdf/rs030n.urdf.xacro | -->
<!-- |    EDITING THIS FILE BY HAND IS NOT RECOMMENDED                                 | -->
<!-- =================================================================================== -->
<robot name="khi_rs030n">
    <transmission name="$join1_trans">
        <type>transmission_interface/SimpleTransmission</type>
        <actuator name="joint1_motor">
            <hardwareInterface>hardware_interface/PositionJointInterface</hardwareInterface>
            <mechanicalReduction>1</mechanicalReduction>
        </actuator>
        <joint name="joint1">
            <hardwareInterface>hardware_interface/PositionJointInterface</hardwareInterface>
        </joint>
    </transmission>
    <transmission name="$join2_trans">
        <type>transmission_interface/SimpleTransmission</type>
        <actuator name="joint2_motor">
            <hardwareInterface>hardware_interface/PositionJointInterface</hardwareInterface>
            <mechanicalReduction>1</mechanicalReduction>
        </actuator>
        <joint name="joint2">
            <hardwareInterface>hardware_interface/PositionJointInterface</hardwareInterface>
        </joint>
    </transmission>
    <transmission name="$join3_trans">
        <type>transmission_interface/SimpleTransmission</type>
        <actuator name="joint3_motor">
            <hardwareInterface>hardware_interface/PositionJointInterface</hardwareInterface>
            <mechanicalReduction>1</mechanicalReduction>
        </actuator>
        <joint name="joint3">
            <hardwareInterface>hardware_interface/PositionJointInterface</hardwareInterface>
        </joint>
    </transmission>
    <transmission name="$join4_trans">
        <type>transmission_interface/SimpleTransmission</type>
        <actuator name="joint4_motor">
            <hardwareInterface>hardware_interface/PositionJointInterface</hardwareInterface>
            <mechanicalReduction>1</mechanicalReduction>
        </actuator>
        <joint name="joint4">
            <hardwareInterface>hardware_interface/PositionJointInterface</hardwareInterface>
        </joint>
    </transmission>
    <transmission name="$join5_trans">
        <type>transmission_interface/SimpleTransmission</type>
        <actuator name="joint5_motor">
            <hardwareInterface>hardware_interface/PositionJointInterface</hardwareInterface>
            <mechanicalReduction>1</mechanicalReduction>
        </actuator>
        <joint name="joint5">
            <hardwareInterface>hardware_interface/PositionJointInterface</hardwareInterface>
        </joint>
    </transmission>
    <transmission name="$join6_trans">
        <type>transmission_interface/SimpleTransmission</type>
        <actuator name="joint6_motor">
            <hardwareInterface>hardware_interface/PositionJointInterface</hardwareInterface>
            <mechanicalReduction>1</mechanicalReduction>
        </actuator>
        <joint name="joint6">
            <hardwareInterface>hardware_interface/PositionJointInterface</hardwareInterface>
        </joint>
    </transmission>
    <!-- gazebo plugin -->
    <gazebo>
        <plugin filename="libgazebo_ros_control.so" name="gazebo_ros_control">
            <robotNamespace>/</robotNamespace>
        </plugin>
        <!--
    <plugin name="gazebo_ros_power_monitor_controller" filename="libgazebo_ros_power_monitor.so">
      <alwaysOn>true</alwaysOn>
      <updateRate>1.0</updateRate>
      <timeout>5</timeout>
      <powerStateTopic>power_state</powerStateTopic>
      <powerStateRate>10.0</powerStateRate>
      <fullChargeCapacity>87.78</fullChargeCapacity>     
      <dischargeRate>-474</dischargeRate>
      <chargeRate>525</chargeRate>
      <dischargeVoltage>15.52</dischargeVoltage>
      <chargeVoltage>16.41</chargeVoltage>
    </plugin>
-->
    </gazebo>
    <!-- link rviz colors -->
    <material name="White">
        <color rgba="1 1 1 1" />
    </material>
    <material name="Black">
        <color rgba="0 0 0 1" />
    </material>
    <!-- rs030n start -->
    <!-- Link 0 -->
    <link name="base_link">
        <visual>
            <geometry>
                <mesh filename="package://khi_rs_description/meshes/RS030N_J0.stl" />
            </geometry>
            <material name="White" />
            <origin rpy="0 0 0" xyz="0 0 0" />
        </visual>
        <collision>
            <geometry>
                <mesh filename="package://khi_rs_description/meshes/RS030N_J0.stl" />
            </geometry>
            <material name="White" />
            <origin rpy="0 0 0" xyz="0 0 0" />
        </collision>
        <inertial>
            <mass value="177.752" />
            <inertia ixx="1.0" ixy="0.0" ixz="0.0" iyy="1.0" iyz="0.0" izz="1.0" />
            <origin xyz="0 0 0" rpy="0 0 0" />
        </inertial>
    </link>
    <!-- Link 1 -->
    <joint name="joint1" type="revolute">
        <axis rpy="0 0 0" xyz="0 0 -1" />
        <limit effort="1000.0" lower="-3.141592653589793" upper="3.141592653589793" velocity="3.141592653589793" />
        <origin rpy="0 0 0" xyz="0 0 0.68" />
        <parent link="base_link" />
        <child link="link1" />
        <dynamics damping="0.0" friction="0.0" />
    </joint>
    <link name="link1">
        <visual>
            <geometry>
                <mesh filename="package://khi_rs_description/meshes/RS030N_J1.stl" />
            </geometry>
            <material name="White" />
            <origin rpy="0 0 0" xyz="0 0 0" />
        </visual>
        <collision>
            <geometry>
                <mesh filename="package://khi_rs_description/meshes/RS030N_J1.stl" />
            </geometry>
            <material name="White" />
            <origin rpy="0 0 0" xyz="0 0 0" />
        </collision>
        <inertial>
            <mass value="216.15" />
            <inertia ixx="1.0" ixy="0.0" ixz="0.0" iyy="1.0" iyz="0.0" izz="1.0" />
            <origin xyz="0 0 0" rpy="0 0 0" />
        </inertial>
    </link>
    <!-- Link 2 -->
    <joint name="joint2" type="revolute">
        <axis rpy="0 0 0" xyz="0 0 1" />
        <limit effort="1000.0" lower="-1.8325957145940461" upper="2.443460952792061" velocity="3.141592653589793" />
        <origin rpy="0 -1.5707963267948966 0" xyz="0 0.15 0" />
        <parent link="link1" />
        <child link="link2" />
        <dynamics damping="0.0" friction="0.0" />
    </joint>
    <link name="link2">
        <visual>
            <geometry>
                <mesh filename="package://khi_rs_description/meshes/RS030N_J2.stl" />
            </geometry>
            <material name="White" />
            <origin rpy="0 1.5707963267948966 0" xyz="0 0 0" />
        </visual>
        <collision>
            <geometry>
                <mesh filename="package://khi_rs_description/meshes/RS030N_J2.stl" />
            </geometry>
            <material name="White" />
            <origin rpy="0 1.5707963267948966 0" xyz="0 0 0" />
        </collision>
        <inertial>
            <mass value="70.847" />
            <inertia ixx="1.0" ixy="0.0" ixz="0.0" iyy="1.0" iyz="0.0" izz="1.0" />
            <origin xyz="0 0 0" rpy="0 0 0" />
        </inertial>
    </link>
    <!-- Link 3 -->
    <joint name="joint3" type="revolute">
        <axis rpy="0 0 0" xyz="0 0 -1" />
        <limit effort="1000.0" lower="-2.705260340591211" upper="2.356194490192345" velocity="3.2288591161895095" />
        <origin rpy="0 0 0" xyz="0.87 0 0" />
        <parent link="link2" />
        <child link="link3" />
        <dynamics damping="0.0" friction="0.0" />
    </joint>
    <link name="link3">
        <visual>
            <geometry>
                <mesh filename="package://khi_rs_description/meshes/RS030N_J3.stl" />
            </geometry>
            <material name="White" />
            <origin rpy="0 1.5707963267948966 0" xyz="0 0 0" />
        </visual>
        <collision>
            <geometry>
                <mesh filename="package://khi_rs_description/meshes/RS030N_J3.stl" />
            </geometry>
            <material name="White" />
            <origin rpy="0 1.5707963267948966 0" xyz="0 0 0" />
        </collision>
        <inertial>
            <mass value="51.71" />
            <inertia ixx="1.0" ixy="0.0" ixz="0.0" iyy="1.0" iyz="0.0" izz="1.0" />
            <origin xyz="0 0 0" rpy="0 0 0" />
        </inertial>
    </link>
    <!-- Link 4 -->
    <joint name="joint4" type="revolute">
        <axis rpy="0 0 0" xyz="0 0 1" />
        <limit effort="1000.0" lower="-6.283185307179586" upper="6.283185307179586" velocity="4.537856055185257" />
        <origin rpy="0 1.5707963267948966 0" xyz="0.267 0 0" />
        <parent link="link3" />
        <child link="link4" />
        <dynamics damping="0.0" friction="0.0" />
    </joint>
    <link name="link4">
        <visual>
            <geometry>
                <mesh filename="package://khi_rs_description/meshes/RS030N_J4.stl" />
            </geometry>
            <material name="White" />
            <origin rpy="0 0 0" xyz="0 0 0.813" />
        </visual>
        <collision>
            <geometry>
                <mesh filename="package://khi_rs_description/meshes/RS030N_J4.stl" />
            </geometry>
            <material name="White" />
            <origin rpy="0 0 0" xyz="0 0 0.813" />
        </collision>
        <inertial>
            <mass value="31.675" />
            <inertia ixx="1.0" ixy="0.0" ixz="0.0" iyy="1.0" iyz="0.0" izz="1.0" />
            <origin xyz="0 0 0" rpy="0 0 0" />
        </inertial>
    </link>
    <!-- Link 5 -->
    <joint name="joint5" type="revolute">
        <axis rpy="0 0 0" xyz="0 0 -1" />
        <limit effort="1000.0" lower="-2.530727415391778" upper="2.530727415391778" velocity="4.537856055185257" />
        <origin rpy="0 -1.5707963267948966 0" xyz="0 0 0.813" />
        <parent link="link4" />
        <child link="link5" />
        <dynamics damping="0.0" friction="0.0" />
    </joint>
    <link name="link5">
        <visual>
            <geometry>
                <mesh filename="package://khi_rs_description/meshes/RS030N_J5.stl" />
            </geometry>
            <material name="White" />
            <origin rpy="0 1.5707963267948966 0" xyz="0 0 0" />
        </visual>
        <collision>
            <geometry>
                <mesh filename="package://khi_rs_description/meshes/RS030N_J5.stl" />
            </geometry>
            <material name="White" />
            <origin rpy="0 1.5707963267948966 0" xyz="0 0 0" />
        </collision>
        <inertial>
            <mass value="6.866" />
            <inertia ixx="1.0" ixy="0.0" ixz="0.0" iyy="1.0" iyz="0.0" izz="1.0" />
            <origin xyz="0 0 0" rpy="0 0 0" />
        </inertial>
    </link>
    <!-- Link 6 -->
    <joint name="joint6" type="revolute">
        <axis rpy="0 0 0" xyz="0 0 1" />
        <limit effort="1000.0" lower="-6.283185307179586" upper="6.283185307179586" velocity="6.283185307179586" />
        <origin rpy="0 1.5707963267948966 0" xyz="0.165 0 0" />
        <parent link="link5" />
        <child link="link6" />
        <dynamics damping="0.0" friction="0.0" />
    </joint>
    <link name="link6">
        <visual>
            <geometry>
                <mesh filename="package://khi_rs_description/meshes/RS030N_J6.stl" />
            </geometry>
            <material name="Black" />
            <origin rpy="0 0 0" xyz="0 0 0" />
        </visual>
        <collision>
            <geometry>
                <mesh filename="package://khi_rs_description/meshes/RS030N_J6.stl" />
            </geometry>
            <material name="Black" />
            <origin rpy="0 0 0" xyz="0 0 0" />
        </collision>
        <inertial>
            <mass value="0.0001" />
            <inertia ixx="1.0" ixy="0.0" ixz="0.0" iyy="1.0" iyz="0.0" izz="1.0" />
            <origin xyz="0 0 0" rpy="0 0 0" />
        </inertial>
    </link>
    <!-- Fix rs030n to world -->
    <link name="world" />
    <joint name="world2base" type="fixed">
        <parent link="world" />
        <child link="base_link" />
        <origin rpy="0 0 0" xyz="0 0 0" />
    </joint>
</robot>

