<?xml version="1.0"?>
<robot xmlns:xacro="http://ros.org/wiki/xacro">
  <xacro:macro name="khi_duaro" params="prefix">

    <xacro:include filename="$(find khi_duaro_description)/urdf/duaro.transmission.xacro" />

    <!-- DH params -->
    <xacro:property name="dh_j1_j2_transy" value="0.36"/>
    <xacro:property name="dh_j2_j3_transy" value="0.40"/>

    <!-- link mass -->
    <xacro:property name="L1_mass" value="11.463"/>
    <xacro:property name="L2_mass" value="3.747"/>
    <xacro:property name="L3_mass" value="3.476"/>
    <xacro:property name="U1_mass" value="11.452"/>
    <xacro:property name="U2_mass" value="3.751"/>
    <xacro:property name="U3_mass" value="3.476"/>

    <!-- link inertia tensor -->
    <xacro:property name="L1_Izz" value="0.503"/>
    <xacro:property name="L2_Izz" value="0.109"/>
    <xacro:property name="U1_Izz" value="0.524"/>
    <xacro:property name="U2_Izz" value="0.109"/>

    <!-- link center lengths -->
    <xacro:property name="L1_length" value="0.162827"/>
    <xacro:property name="L2_length" value="0.124537"/>
    <xacro:property name="U1_length" value="-0.169738"/>
    <xacro:property name="U2_length" value="0.124648"/>

    <!-- joint limits [rad][m] -->
    <xacro:property name="J1_LOWER_lower_limit" value="${radians(-170)}"/>
    <xacro:property name="J1_LOWER_upper_limit" value="${radians( 170)}"/>
    <xacro:property name="J2_LOWER_lower_limit" value="${radians(-140)}"/>
    <xacro:property name="J2_LOWER_upper_limit" value="${radians( 140)}"/>
    <xacro:property name="J3_LOWER_lower_limit" value="0"/>
    <xacro:property name="J3_LOWER_upper_limit" value="0.15"/>
    <xacro:property name="J4_LOWER_lower_limit" value="${radians(-360)}"/>
    <xacro:property name="J4_LOWER_upper_limit" value="${radians( 360)}"/>

    <xacro:property name="J1_UPPER_lower_limit" value="${radians(-140)}"/>
    <xacro:property name="J1_UPPER_upper_limit" value="${radians( 500)}"/>
    <xacro:property name="J2_UPPER_lower_limit" value="${radians(-140)}"/>
    <xacro:property name="J2_UPPER_upper_limit" value="${radians( 140)}"/>
    <xacro:property name="J3_UPPER_lower_limit" value="0"/>
    <xacro:property name="J3_UPPER_upper_limit" value="0.15"/>
    <xacro:property name="J4_UPPER_lower_limit" value="${radians(-360)}"/>
    <xacro:property name="J4_UPPER_upper_limit" value="${radians( 360)}"/>

    <!-- joint velocity limits [rad/s][m/s]-->
    <xacro:property name="J1_velocity_limit" value="${radians(240)}"/>
    <xacro:property name="J2_velocity_limit" value="${radians(315)}"/>
    <xacro:property name="J3_velocity_limit" value="0.3"/>
    <xacro:property name="J4_velocity_limit" value="${radians(600)}"/>

    <!-- link rviz color-->
    <material name="Light_blue">
      <color rgba="0 1.0 1.0 1.0"/>
    </material>

    <material name="White">
      <color rgba="1.0 1.0 1.0 1.0"/>
    </material>

    <material name="Black">
      <color rgba="0 0 0 1.0"/>
    </material>

    <material name="Red">
      <color rgba="1.0 0 0 1.0"/>
    </material>

    <!-- link inertial-->
    <xacro:macro name="default_inertial" params="mass">
      <inertial>
        <mass value="${mass}" />
        <inertia ixx="1.0" ixy="0.0" ixz="0.0" iyy="1.0" iyz="0.0" izz="1.0" />
      </inertial>
    </xacro:macro>

    <xacro:macro name="link_inertial" params="mass Izz length">
      <inertial>
        <mass value="${mass}" />
        <inertia ixx="1.0" ixy="0.0" ixz="0.0" iyy="1.0" iyz="0.0" izz="${Izz+length*length*mass}" />
      </inertial>
    </xacro:macro>

    <link name="${prefix}base_link">
      <visual>
        <geometry>
          <mesh filename="package://khi_duaro_description/meshes/WD002N_F502_Adjuster_pad.stl"/>
        </geometry>
        <material name="White"/>
        <origin rpy="0 0 0" xyz="0 0 0"/>
      </visual>
      <collision>
        <geometry>
          <mesh filename="package://khi_duaro_description/meshes/WD002N_F502_Adjuster_pad.stl"/>
        </geometry>
        <material name="White"/>
        <origin rpy="0 0 0" xyz="0 0 0"/>
      </collision>
    </link>


    <!-- fixed parts xacro-->
    <xacro:macro name="fixed_parts" params="prefix:=^ color name filename height rot mass">

      <link name="${prefix}${name}">
        <visual>
          <geometry>
            <mesh filename="package://khi_duaro_description/meshes/${filename}.stl"/>
          </geometry>
          <material name="${color}"/>
          <origin rpy="0 0 ${rot}" xyz="0 0 0"/>
        </visual>
        <collision>
          <geometry>
            <mesh filename="package://khi_duaro_description/meshes/${filename}.stl"/>
          </geometry>
          <origin rpy="0 0 0" xyz="0 0 0"/>
        </collision>
        <xacro:default_inertial mass="${mass}"/>
      </link>

      <joint name="${prefix}${name}_joint" type="fixed">
        <parent link="${prefix}base_link"/>
        <child link="${prefix}${name}"/>
        <origin xyz="0 0 ${height}" rpy="0 0 0" />
      </joint>

    </xacro:macro>

    <!-- fixed parts  -->
    <xacro:fixed_parts color="White" name="duaro_body" filename="WD002N_F502_Cabinet_body" height="0" rot="0" mass="100"/>
    <xacro:fixed_parts color="Light_blue" name="duaro_j0_cover" filename="WD002N_A201_j0_cover_Ver2m" height="0.82" rot="0" mass="2"/>
    <xacro:fixed_parts color="Black" name="duaro_logo" filename="WD002N_F502_LOGO_duAro" height="0" rot="0" mass="1"/>
    <xacro:fixed_parts color="Red" name="kawasaki_logo" filename="WD002N_F502_LOGO_Kawasaki" height="0" rot="0" mass="1"/>
    <xacro:fixed_parts color="Light_blue" name="duaro_body_cover" filename="WD002N_F502_Cabinet_front_cover" height="0" rot="0" mass="1"/>
    <xacro:fixed_parts color="White" name="cart" filename="WD002N_F502_Cart" height="0" rot="0" mass="2"/>
  
    <link name="${prefix}duaro_j0">
      <visual>
        <geometry>
          <mesh filename="package://khi_duaro_description/meshes/WD002N_A201_j0_Ver2m.stl"/>
        </geometry>
        <material name="White"/>
        <origin rpy="0 0 0" xyz="0 0 0"/>
      </visual>
      <collision>
        <geometry>
          <mesh filename="package://khi_duaro_description/meshes/WD002N_A201_j0_Ver2m.stl"/>
        </geometry>
        <origin rpy="0 0 0" xyz="0 0 0"/>
      </collision>
      <xacro:default_inertial mass="10"/>
    </link>


    <joint name="${prefix}joint0" type="fixed">
      <origin xyz="0 0 0.82"/>
      <parent link="${prefix}duaro_body"/>
      <child link="${prefix}duaro_j0"/>
    </joint>

    <!-- lower arm -->
    <link name="${prefix}lower_link_j1">
      <visual>
        <geometry>
          <mesh filename="package://khi_duaro_description/meshes/WD002N_A201L_J1_Ver2m.stl"/>
        </geometry>
        <material name="White"/>
        <origin rpy="0 0 0" xyz="0 0 0"/>
      </visual>
      <collision>
        <geometry>
          <mesh filename="package://khi_duaro_description/meshes/WD002N_A201L_J1_Ver2m.stl"/>
        </geometry>
        <material name="White"/>
        <origin rpy="0 0 0" xyz="0 0 0"/>
      </collision>
      <xacro:link_inertial Izz="${L1_Izz}" length="${L1_length}" mass="${L1_mass}"/>
    </link>

    <joint name="${prefix}lower_joint1" type="revolute">
        <axis xyz="0 0 1" rpy="0 0 0" />
        <limit effort="100.0" lower="${J1_LOWER_lower_limit}" upper="${J1_LOWER_upper_limit}" velocity="${J1_velocity_limit}"/>
        <origin xyz="0 0 0.2515" rpy="0 0 0"/>
        <parent link="${prefix}duaro_j0"/>
        <child link="${prefix}lower_link_j1"/>
        <dynamics damping="0.0" friction="0.0"/>
    </joint>


    <link name="${prefix}lower_link_j2">
      <visual>
        <geometry>
          <mesh filename="package://khi_duaro_description/meshes/WD002N_A202L_J2m.stl"/>
        </geometry>
        <material name="White"/>
        <origin rpy="0 0 0" xyz="0 0 0"/>
      </visual>
      <collision>
        <geometry>
          <mesh filename="package://khi_duaro_description/meshes/WD002N_A202L_J2m.stl"/>
        </geometry>
        <material name="White"/>
        <origin rpy="0 0 0" xyz="0 0 0"/>
      </collision>
      <xacro:link_inertial Izz="${L2_Izz}" length="${L2_length}" mass="${L2_mass}"/>
    </link>

    <joint name="${prefix}lower_joint2" type="revolute">
      <axis xyz="0 0 1" rpy="0 0 0" />
      <limit effort="100.0" lower="${J2_LOWER_lower_limit}" upper="${J2_LOWER_upper_limit}" velocity="${J2_velocity_limit}"/>
      <origin xyz="0 ${dh_j1_j2_transy} 0.0905"/>
      <parent link="${prefix}lower_link_j1"/>
      <child link="${prefix}lower_link_j2"/>
      <dynamics damping="0.0" friction="0.0"/>
    </joint>

    <link name="${prefix}lower_link_j3">
      <visual>
        <geometry>
          <mesh filename="package://khi_duaro_description/meshes/WD002N_A202L_J3m.stl"/>
        </geometry>
       <material name="White"/>
        <origin rpy="0 0 0" xyz="0 0 0"/>
      </visual>
      <collision>
        <geometry>
          <mesh filename="package://khi_duaro_description/meshes/WD002N_A202L_J3m.stl"/>
        </geometry>
        <material name="White"/>
        <origin rpy="0 0 0" xyz="0 0 0"/>
      </collision>
      <xacro:default_inertial mass="${L3_mass}"/>
    </link>

    <joint name="${prefix}lower_joint3" type="prismatic">
      <axis xyz="0 0 1" rpy="0 0 0" />
      <limit effort="100.0" lower="${J3_LOWER_lower_limit}" upper="${J3_LOWER_upper_limit}" velocity="${J3_velocity_limit}"/>
      <origin xyz="0 ${dh_j2_j3_transy} 0.03850"/>
      <parent link="${prefix}lower_link_j2"/>
      <child link="${prefix}lower_link_j3"/>
    </joint>

    <link name="${prefix}lower_link_j3_obst">
      <visual>
        <geometry>
          <mesh filename="package://khi_duaro_description/meshes/WD002N_A202L_J3_obstaclem.stl"/>
        </geometry>
        <material name="Black"/>
        <origin rpy="0 0 0" xyz="0 0 0"/>
      </visual>
    </link>

    <joint name="${prefix}lower_j3_obstaclem_joint" type="fixed">
      <origin rpy="0 0 0" xyz="0 0 0"/>
      <parent link="${prefix}lower_link_j3"/>
      <child link="${prefix}lower_link_j3_obst"/>
    </joint>

    <link name="${prefix}lower_link_j4">
      <visual>
        <geometry>
          <mesh filename="package://khi_duaro_description/meshes/WD002N_A202L_J4m.stl"/>
        </geometry>
       <material name=""/>
        <origin rpy="0 0 0" xyz="0 0 0"/>
      </visual>
      <collision>
        <geometry>
          <mesh filename="package://khi_duaro_description/meshes/WD002N_A202L_J4m.stl"/>
        </geometry>
        <material name="White"/>
        <origin rpy="0 0 0" xyz="0 0 0"/>
      </collision>
      <xacro:default_inertial mass="0.5"/>
    </link>

    <joint name="${prefix}lower_joint4" type="revolute">
      <axis xyz="0 0 1" rpy="0 0 0" />
      <limit effort="100.0" lower="${J4_LOWER_lower_limit}" upper="${J4_LOWER_upper_limit}" velocity="${J4_velocity_limit}"/>
      <origin xyz="0 0 -0.24"/>
      <parent link="${prefix}lower_link_j3"/>
      <child link="${prefix}lower_link_j4"/>
      <dynamics damping="0.0" friction="0.0"/>
    </joint>

    <!-- upper arm -->
    <link name="${prefix}upper_link_j1">
      <visual>
        <geometry>
          <mesh filename="package://khi_duaro_description/meshes/WD002N_A201U_J1_Ver2m.stl"/>
        </geometry>
        <material name="White"/>
        <origin xyz="0 0 0"/>
      </visual>
      <collision>
        <geometry>
          <mesh filename="package://khi_duaro_description/meshes/WD002N_A201U_J1_Ver2m.stl"/>
        </geometry>
        <material name="White"/>
        <origin rpy="0 0 0" xyz="0 0 0"/>
      </collision>
      <xacro:link_inertial Izz="${U1_Izz}" length="${U1_length}" mass="${U1_mass}"/>
    </link>

    <joint name="${prefix}upper_joint1" type="revolute">
      <origin rpy="0 0 0" xyz="0 0 0.3805"/>
        <axis xyz="0 0 1" rpy="0 0 0" />
        <limit effort="100.0" lower="${J1_UPPER_lower_limit}" upper="${J1_UPPER_upper_limit}" velocity="${J1_velocity_limit}"/>
        <parent link="${prefix}duaro_j0"/>
        <child link="${prefix}upper_link_j1"/>
        <dynamics damping="0.0" friction="0.0"/>
    </joint>


    <link name="${prefix}upper_link_j2">
      <visual>
        <geometry>
          <mesh filename="package://khi_duaro_description/meshes/WD002N_A202U_J2m.stl"/>
        </geometry>
        <material name="White"/>
        <origin rpy="0 0 0" xyz="0 0 0"/>
      </visual>
      <collision>
        <geometry>
          <mesh filename="package://khi_duaro_description/meshes/WD002N_A202U_J2m.stl"/>
        </geometry>
        <material name="White"/>
        <origin rpy="0 0 0" xyz="0 0 0"/>
      </collision>
      <xacro:link_inertial Izz="${U2_Izz}" length="${U2_length}" mass="${U2_mass}"/>
    </link>

    <joint name="${prefix}upper_joint2" type="revolute">
      <axis xyz="0 0 1" rpy="0 0 0" />
      <limit effort="100.0" lower="${J2_UPPER_lower_limit}" upper="${J2_UPPER_upper_limit}" velocity="${J2_velocity_limit}"/>
      <origin xyz="0 ${dh_j1_j2_transy} 0"/>
      <parent link="${prefix}upper_link_j1"/>
      <child link="${prefix}upper_link_j2"/>
      <dynamics damping="0.0" friction="0.0"/>
    </joint>

    <link name="${prefix}upper_link_j3">
      <visual>
        <geometry>
          <mesh filename="package://khi_duaro_description/meshes/WD002N_A202U_J3m.stl"/>
        </geometry>
       <material name="White"/>
        <origin rpy="0 0 0" xyz="0 0 0"/>
      </visual>
      <collision>
        <geometry>
          <mesh filename="package://khi_duaro_description/meshes/WD002N_A202U_J3m.stl"/>
        </geometry>
        <material name="White"/>
        <origin rpy="0 0 0" xyz="0 0 0"/>
      </collision>
      <xacro:default_inertial mass="${U3_mass}"/>
    </link>

    <joint name="${prefix}upper_joint3" type="prismatic">
      <axis xyz="0 0 1" rpy="0 0 0" />
      <limit effort="100.0" lower="${J3_UPPER_lower_limit}" upper="${J3_UPPER_upper_limit}" velocity="${J3_velocity_limit}"/>
      <origin xyz="0 ${dh_j2_j3_transy} 0"/>
      <parent link="${prefix}upper_link_j2"/>
      <child link="${prefix}upper_link_j3"/>
    </joint>

    <link name="${prefix}upper_link_j3_obst">
      <visual>
        <geometry>
          <mesh filename="package://khi_duaro_description/meshes/WD002N_A202U_J3_obstaclem.stl"/>
        </geometry>
       <material name="Black"/>
        <origin rpy="0 0 0" xyz="0 0 0"/>
      </visual>
    </link>

    <joint name="${prefix}upper_j3_obstaclem_joint" type="fixed">
      <origin xyz="0 0 0"/>
      <parent link="${prefix}upper_link_j3"/>
      <child link="${prefix}upper_link_j3_obst"/>
    </joint>

   <link name="${prefix}upper_link_j4">
      <visual>
        <geometry>
          <mesh filename="package://khi_duaro_description/meshes/WD002N_A202U_J4m.stl"/>
        </geometry>
       <material name=""/>
        <origin rpy="0 0 0" xyz="0 0 0"/>
      </visual>
      <collision>
        <geometry>
          <mesh filename="package://khi_duaro_description/meshes/WD002N_A202U_J4m.stl"/>
        </geometry>
        <material name="White"/>
        <origin rpy="0 0 0" xyz="0 0 0"/>
      </collision>
      <xacro:default_inertial mass="10"/>
    </link>

    <joint name="${prefix}upper_joint4" type="revolute">
      <axis xyz="0 0 1" rpy="0 0 0" />
      <limit effort="100.0" lower="${J4_UPPER_lower_limit}" upper="${J4_UPPER_upper_limit}" velocity="${J3_velocity_limit}"/>
      <origin xyz="0 0 -0.24"/>
      <parent link="${prefix}upper_link_j3"/>
      <child link="${prefix}upper_link_j4"/>
      <dynamics damping="0.0" friction="0.0"/>
    </joint>

    <!-- parts gazebo colors -->
    <xacro:macro name="gazebo_color" params="parts colors">
    <gazebo reference="${parts}">
      <material>Gazebo/${colors}</material>
    </gazebo>
    </xacro:macro>
    <xacro:gazebo_color parts="${prefix}duaro_body" colors="White"/>
    <xacro:gazebo_color parts="${prefix}pedestal_obstacle" colors="Light_blue"/>
    <xacro:gazebo_color parts="${prefix}duaro_logo" colors="Black"/>
    <xacro:gazebo_color parts="${prefix}base_link" colors="White"/>
    <xacro:gazebo_color parts="${prefix}duaro_j0" colors="White"/>
    <xacro:gazebo_color parts="${prefix}duaro_j0_cover" colors="Light_blue"/>
    <xacro:gazebo_color parts="${prefix}lower_link_j1" colors="White"/>
    <xacro:gazebo_color parts="${prefix}lower_link_j2" colors="White"/>
    <xacro:gazebo_color parts="${prefix}lower_link_j3" colors="White"/>
    <xacro:gazebo_color parts="${prefix}lower_link_j4" colors="White"/>
    <xacro:gazebo_color parts="${prefix}lower_link_j3_obst" colors="Black"/>
    <xacro:gazebo_color parts="${prefix}upper_link_j1" colors="White"/>
    <xacro:gazebo_color parts="${prefix}upper_link_j2" colors="White"/>
    <xacro:gazebo_color parts="${prefix}upper_link_j3" colors="White"/>
    <xacro:gazebo_color parts="${prefix}upper_link_j4" colors="White"/>
    <xacro:gazebo_color parts="${prefix}upper_link_j3_obst" colors="Black"/>
    <xacro:gazebo_color parts="${prefix}duaro_body" colors="White"/>

    <!-- duaro end -->
    <gazebo>
      <plugin name="gazebo_ros_control" filename="libgazebo_ros_control.so">
        <robotNamespace>/</robotNamespace>
      </plugin>
    </gazebo>
  </xacro:macro>
</robot>
